┌─[root@parrot]─[~/hackthebox/luke]     
└──╼ #cd extra/                         
┌─[root@parrot]─[~/hackthebox/luke/extra]                                        
└──╼ #ls                                
jwt-token.py                            
┌─[root@parrot]─[~/hackthebox/luke/extra]                                        
└──╼ #curl http://10.10.10.137:3000/ -H 'Authorization: Bearer eyJ0eXAiOiJKV1QiLCJhbGciOiJIUzI1NiJ9.eyJ1c2VybmFtZSI6ImFkbWluIiwiaWF0IjoiMCJ9.JjszoyYbYTqft8Ghq_3d3YXyGxxW7usaSC0hQYj1BkY'                 
{"message":"Welcome admin ! "}┌─[root@parrot]─[~/hackthebox/luke/extra]          
└──╼ #vi jwt-token.py                   
┌─[root@parrot]─[~/hackthebox/luke/extra]                                        
└──╼ #python3 jwt-token.py              
eyJ0eXAiOiJKV1QiLCJhbGciOiJIUzI1NiJ9.eyJ1c2VybmFtZSI6ImFkbWluIiwiaWF0IjoiMCJ9.JjszoyYbYTqft8Ghq_3d3YXyGxxW7usaSC0hQYj1BkY                                         
Traceback (most recent call last):      
  File "/usr/lib/python3/dist-packages/urllib3/contrib/pyopenssl.py", line 485, in wrap_socket                                                                    
    cnx.do_handshake()                  
  File "/usr/lib/python3/dist-packages/OpenSSL/SSL.py", line 1915, in do_handshake                                                                                
    self._raise_ssl_error(self._ssl, result)                                     
  File "/usr/lib/python3/dist-packages/OpenSSL/SSL.py", line 1647, in _raise_ssl_error                                                                            
    _raise_current_error()              
  File "/usr/lib/python3/dist-packages/OpenSSL/_util.py", line 54, in exception_from_error_queue                                                                  
    raise exception_type(errors)        
OpenSSL.SSL.Error: [('SSL routines', 'ssl3_get_record', 'wrong version number')] 

During handling of the above exception, another exception occurred:              

Traceback (most recent call last):      
  File "/usr/lib/python3/dist-packages/urllib3/connectionpool.py", line 672, in urlopen                                                                           
    chunked=chunked,                    
  File "/usr/lib/python3/dist-packages/urllib3/connectionpool.py", line 376, in _make_request                                                                     
    self._validate_conn(conn)           
  File "/usr/lib/python3/dist-packages/urllib3/connectionpool.py", line 996, in _validate_conn                                                                    
    conn.connect()                      
  File "/usr/lib/python3/dist-packages/urllib3/connection.py", line 394, in connect                                                                               
    ssl_context=context,                
  File "/usr/lib/python3/dist-packages/urllib3/util/ssl_.py", line 383, in ssl_wrap_socket                                                                        
    return context.wrap_socket(sock)    
  File "/usr/lib/python3/dist-packages/urllib3/contrib/pyopenssl.py", line 491, in wrap_socket                                                                    
    raise ssl.SSLError("bad handshake: %r" % e)                                  
ssl.SSLError: ("bad handshake: Error([('SSL routines', 'ssl3_get_record', 'wrong version number')])",)                                                            

During handling of the above exception, another exception occurred:              

Traceback (most recent call last):      
  File "/usr/lib/python3/dist-packages/requests/adapters.py", line 449, in send  
    timeout=timeout                     
  File "/usr/lib/python3/dist-packages/urllib3/connectionpool.py", line 720, in urlopen                                                                           
    method, url, error=e, _pool=self, _stacktrace=sys.exc_info()[2]              
  File "/usr/lib/python3/dist-packages/urllib3/util/retry.py", line 436, in increment                                                                             
    raise MaxRetryError(_pool, url, error or ResponseError(cause))               
urllib3.exceptions.MaxRetryError: HTTPSConnectionPool(host='10.10.10.137', port=3000): Max retries exceeded with url: / (Caused by SSLError(SSLError("bad handshake: Error([('SSL routines', 'ssl3_get_record', 'wrong version number')])")))      

During handling of the above exception, another exception occurred:              

Traceback (most recent call last):      
  File "jwt-token.py", line 10, in <module>                                      
    r = requests.get('https://10.10.10.137:3000/',headers=headers)               
  File "/usr/lib/python3/dist-packages/requests/api.py", line 75, in get         
    return request('get', url, params=params, **kwargs)                          
  File "/usr/lib/python3/dist-packages/requests/api.py", line 60, in request     
    return session.request(method=method, url=url, **kwargs)                     
  File "/usr/lib/python3/dist-packages/requests/sessions.py", line 533, in request                                                                                
    resp = self.send(prep, **send_kwargs)                                        
  File "/usr/lib/python3/dist-packages/requests/sessions.py", line 646, in send  
    r = adapter.send(request, **kwargs) 
  File "/usr/lib/python3/dist-packages/requests/adapters.py", line 514, in send  
    raise SSLError(e, request=request)  
requests.exceptions.SSLError: HTTPSConnectionPool(host='10.10.10.137', port=3000): Max retries exceeded with url: / (Caused by SSLError(SSLError("bad handshake: Error([('SSL routines', 'ssl3_get_record', 'wrong version number')])")))          
┌─[✗]─[root@parrot]─[~/hackthebox/luke/extra]                                    
└──╼ #python3 jwt-token.py              
eyJ0eXAiOiJKV1QiLCJhbGciOiJIUzI1NiJ9.eyJ1c2VybmFtZSI6ImFkbWluIiwiaWF0IjoiMCJ9.JjszoyYbYTqft8Ghq_3d3YXyGxxW7usaSC0hQYj1BkY                                         
Traceback (most recent call last):      
  File "/usr/lib/python3/dist-packages/urllib3/contrib/pyopenssl.py", line 485, in wrap_socket                                                                    
    cnx.do_handshake()                  
  File "/usr/lib/python3/dist-packages/OpenSSL/SSL.py", line 1915, in do_handshake                                                                                
    self._raise_ssl_error(self._ssl, result)                                     
  File "/usr/lib/python3/dist-packages/OpenSSL/SSL.py", line 1647, in _raise_ssl_error                                                                            
    _raise_current_error()              
  File "/usr/lib/python3/dist-packages/OpenSSL/_util.py", line 54, in exception_from_error_queue                                                                  
    raise exception_type(errors)        
OpenSSL.SSL.Error: [('SSL routines', 'ssl3_get_record', 'wrong version number')] 

During handling of the above exception, another exception occurred:              

Traceback (most recent call last):      
  File "/usr/lib/python3/dist-packages/urllib3/connectionpool.py", line 672, in urlopen                                                                           
    chunked=chunked,                    
  File "/usr/lib/python3/dist-packages/urllib3/connectionpool.py", line 376, in _make_request                                                                     
    self._validate_conn(conn)           
  File "/usr/lib/python3/dist-packages/urllib3/connectionpool.py", line 996, in _validate_conn                                                                    
    conn.connect()                      
  File "/usr/lib/python3/dist-packages/urllib3/connection.py", line 394, in connect                                                                               
    ssl_context=context,                
  File "/usr/lib/python3/dist-packages/urllib3/util/ssl_.py", line 383, in ssl_wrap_socket                                                                        
    return context.wrap_socket(sock)    
  File "/usr/lib/python3/dist-packages/urllib3/contrib/pyopenssl.py", line 491, in wrap_socket                                                                    
    raise ssl.SSLError("bad handshake: %r" % e)                                  
ssl.SSLError: ("bad handshake: Error([('SSL routines', 'ssl3_get_record', 'wrong version number')])",)                                                            

During handling of the above exception, another exception occurred:              

Traceback (most recent call last):      
  File "/usr/lib/python3/dist-packages/requests/adapters.py", line 449, in send  
    timeout=timeout                     
  File "/usr/lib/python3/dist-packages/urllib3/connectionpool.py", line 720, in urlopen                                                                           
    method, url, error=e, _pool=self, _stacktrace=sys.exc_info()[2]              
  File "/usr/lib/python3/dist-packages/urllib3/util/retry.py", line 436, in increment                                                                             
    raise MaxRetryError(_pool, url, error or ResponseError(cause))               
urllib3.exceptions.MaxRetryError: HTTPSConnectionPool(host='10.10.10.137', port=3000): Max retries exceeded with url: / (Caused by SSLError(SSLError("bad handshake: Error([('SSL routines', 'ssl3_get_record', 'wrong version number')])")))      

During handling of the above exception, another exception occurred:              

Traceback (most recent call last):      
  File "jwt-token.py", line 10, in <module>                                      
    r = requests.get('https://10.10.10.137:3000/',headers=headers)               
  File "/usr/lib/python3/dist-packages/requests/api.py", line 75, in get         
    return request('get', url, params=params, **kwargs)                          
  File "/usr/lib/python3/dist-packages/requests/api.py", line 60, in request     
    return session.request(method=method, url=url, **kwargs)                     
  File "/usr/lib/python3/dist-packages/requests/sessions.py", line 533, in request                                                                                
    resp = self.send(prep, **send_kwargs)                                        
  File "/usr/lib/python3/dist-packages/requests/sessions.py", line 646, in send  
    r = adapter.send(request, **kwargs) 
  File "/usr/lib/python3/dist-packages/requests/adapters.py", line 514, in send  
    raise SSLError(e, request=request)  
requests.exceptions.SSLError: HTTPSConnectionPool(host='10.10.10.137', port=3000): Max retries exceeded with url: / (Caused by SSLError(SSLError("bad handshake: Error([('SSL routines', 'ssl3_get_record', 'wrong version number')])")))          
┌─[✗]─[root@parrot]─[~/hackthebox/luke/extra]                                    
└──╼ #^C                                
┌─[✗]─[root@parrot]─[~/hackthebox/luke/extra]                                    
└──╼ #python3 jwt-token.py ^C                                                                                                                                     
┌─[✗]─[root@parrot]─[~/hackthebox/luke/extra]                                    
└──╼ #vi jwt-token.py                                                                                                                                             
┌─[root@parrot]─[~/hackthebox/luke/extra]                                        
└──╼ #python3 jwt-token.py                                                                                                                                        
eyJ0eXAiOiJKV1QiLCJhbGciOiJIUzI1NiJ9.eyJ1c2VybmFtZSI6ImFkbWluIiwiaWF0IjoiMCJ9.JjszoyYbYTqft8Ghq_3d3YXyGxxW7usaSC0hQYj1BkY                                         
{"message":"Welcome admin ! "}          
┌─[root@parrot]─[~/hackthebox/luke/extra]                                        
└──╼ #                                  
